<?xml version="1.0" encoding="utf-8"?>
<!-- =================================================================================== -->
<!-- |    This document was autogenerated by xacro from /home/csevastopoulos/catkin_ws/src/kymco_maxxer90_robot/kymco_maxxer90_description/urdf/kymco_maxxer90.urdf.xacro | -->
<!-- |    EDITING THIS FILE BY HAND IS NOT RECOMMENDED                                 | -->
<!-- =================================================================================== -->
<robot name="kymco_maxxer90">
  <!-- Chassis -->
  <link name="base_link"/>
  <link name="chassis_link">
    <visual>
      <origin rpy="0 0 0" xyz="0 0 0.35"/>
      <geometry>
        <mesh filename="package://kymco_maxxer90_description/meshes/chassis.stl" scale="1.0 1.0 1.0"/>
      </geometry>
      <material name="black">
        <color rgba="0 0 0 1"/>
      </material>
    </visual>
    <collision>
      <origin rpy="0 0 0" xyz="0 0 0.35"/>
      <geometry>
        <mesh filename="package://kymco_maxxer90_description/meshes/chassis.stl" scale="1.0 1.0 1.0"/>
      </geometry>
    </collision>
  </link>
  <joint name="chassis_joint" type="fixed">
    <origin rpy="0 0 0" xyz="0 0 0"/>
    <parent link="base_link"/>
    &quot;
        
    <child link="chassis_link"/>
    &quot;
    
  </joint>
  <link name="inertia_link">
    <inertial>
      <mass value="68"/>
      <origin xyz="0 -0.2 0.37"/>
      <inertia ixx="11.746671789898144" ixy="0" ixz="0" iyy="2.629571305145487" iyz="0" izz="10.930434142335272"/>
    </inertial>
  </link>
  <joint name="inertia_joint" type="fixed">
    <origin rpy="0 0 0" xyz="0 0 0"/>
    <parent link="base_link"/>
    <child link="inertia_link"/>
  </joint>
  <gazebo reference="chassis_link">
    <material>Gazebo/Black</material>
  </gazebo>
  &quot;

    
  <!-- Steering wheel -->
  <link name="steering_wheel_link">
    <inertial>
      <mass value="1"/>
      <origin xyz="0 0 0"/>
      <inertia ixx="0.01" ixy="0" ixz="0" iyy="0.01" iyz="0" izz="0.01"/>
    </inertial>
  </link>
  <joint name="steering_wheel_joint" type="revolute">
    <origin rpy="0 0 0" xyz="0 0 0"/>
    <parent link="base_link"/>
    <child link="steering_wheel_link"/>
    <axis xyz="0 0 1"/>
    <!-- TODO effort and velocity -->
    <limit effort="100.5" lower="-0.436332312999" upper="0.436332312999" velocity="4.5"/>
    <dynamics damping="3" friction="0.0"/>
  </joint>
  <transmission name="steering_wheel_joint_trans">
    <type>transmission_interface/SimpleTransmission</type>
    <joint name="steering_wheel_joint">
      <hardwareInterface>hardware_interface/PositionJointInterface</hardwareInterface>
    </joint>
    <actuator name="steering_wheel_actuator">
      <mechanicalReduction>1</mechanicalReduction>
    </actuator>
  </transmission>
  <!-- Engine -->
  <link name="engine_link">
    <visual>
      <origin rpy="0 0 0" xyz="0 0 0"/>
      <geometry>
        <mesh filename="package://kymco_maxxer90_description/meshes/engine.stl" scale="1.0 1.0 1.0"/>
      </geometry>
      <material name="silver">
        <color rgba="0.3 0.3 0.3 1"/>
      </material>
    </visual>
    <collision>
      <origin rpy="0 0 0" xyz="0 0 0"/>
      <geometry>
        <mesh filename="package://kymco_maxxer90_description/meshes/engine.stl" scale="1.0 1.0 1.0"/>
      </geometry>
    </collision>
  </link>
  <joint name="engine_joint" type="fixed">
    <origin rpy="0 0 1.57079632679" xyz="0 -0.08 0.4"/>
    <parent link="base_link"/>
    <child link="engine_link"/>
  </joint>
  <gazebo reference="engine_link">
    <material>Gazebo/Grey</material>
  </gazebo>
  &quot;

    
  <link name="front_right_wheel_link">
    <inertial>
      <mass value="15.0"/>
      <origin xyz="0 0 0"/>
      <inertia ixx="0.28813432952881635" ixy="0" ixz="0" iyy="0.5212991167201597" iyz="0" izz="0.2894147916616918"/>
    </inertial>
    <visual>
      <origin rpy="0 0 0" xyz="0 0 0"/>
      <geometry>
        <mesh filename="package://kymco_maxxer90_description/meshes/wheel.stl" scale="1.0 1.0 1.0"/>
      </geometry>
      <material name="black"/>
    </visual>
    <collision>
      <origin rpy="0 0 0" xyz="0 0 0"/>
      <geometry>
        <mesh filename="package://kymco_maxxer90_description/meshes/wheel.stl" scale="1.0 1.0 1.0"/>
      </geometry>
    </collision>
  </link>
  <link name="front_right_wheel_steering_link">
    <inertial>
      <mass value="1"/>
      <origin xyz="0 0 0"/>
      <inertia ixx="0.01" ixy="0" ixz="0" iyy="0.01" iyz="0" izz="0.01"/>
    </inertial>
  </link>
  <joint name="front_right_steering_wheel_joint" type="revolute">
    <origin rpy="0 0 1.57079632679" xyz="0.275 0.33 0.175"/>
    <parent link="base_link"/>
    <child link="front_right_wheel_steering_link"/>
    <axis xyz="0 0 1"/>
    <mimic joint="steering_wheel_joint" multiplier="1" offset="0"/>
    <!-- TODO effort and velocity -->
    <limit effort="100.5" lower="-0.436332312999" upper="0.436332312999" velocity="4.5"/>
    <dynamics damping="3" friction="0.0"/>
  </joint>
  <joint name="front_right_wheel" type="continuous">
    <origin rpy="0 0 0" xyz="0 0 0"/>
    <parent link="front_right_wheel_steering_link"/>
    <child link="front_right_wheel_link"/>
    <axis rpy="0 0 0" xyz="0 1 0"/>
  </joint>
  <gazebo reference="front_right_wheel_link">
    <material>Gazebo/Black</material>
  </gazebo>
  &quot;

        
  <gazebo>
    <plugin filename="libroboticsgroup_gazebo_mimic_joint_plugin.so" name="front_right_mimic_joint_plugin">
      <joint>steering_wheel_joint</joint>
      <mimicJoint>front_right_steering_wheel_joint</mimicJoint>
      <hasPID/>
      <multiplier>1.0</multiplier>
      <offset>0</offset>
      <sensitiveness>0.1</sensitiveness>
      <maxEffort>100000.0</maxEffort>
    </plugin>
  </gazebo>
  <!-- <transmission name="${wheel_prefix}_wheel_steering_joint_trans"> -->
  <!-- <type>transmission_interface/SimpleTransmission</type> -->
  <!-- <joint name="${wheel_prefix}_steering_wheel_joint"> -->
  <!-- <hardwareInterface>hardware_interface/PositionJointInterface</hardwareInterface> -->
  <!-- </joint> -->
  <!-- <actuator name="${wheel_prefix}_steering_wheel_actuator"> -->
  <!-- <mechanicalReduction>1</mechanicalReduction> -->
  <!-- </actuator> -->
  <!-- </transmission> -->
  <!-- <transmission name="${wheel_prefix}_wheel_trans" type="SimpleTransmission"> -->
  <!-- <type>transmission_interface/SimpleTransmission</type> -->
  <!-- <actuator name="${wheel_prefix}_wheel_motor"> -->
  <!-- <mechanicalReduction>0</mechanicalReduction> -->
  <!-- </actuator> -->
  <!-- <joint name="${wheel_prefix}_wheel"> -->
  <!-- <hardwareInterface>hardware_interface/VelocityJointInterface</hardwareInterface> -->
  <!-- </joint> -->
  <!-- </transmission> -->
  <link name="front_left_wheel_link">
    <inertial>
      <mass value="15.0"/>
      <origin xyz="0 0 0"/>
      <inertia ixx="0.28813432952881635" ixy="0" ixz="0" iyy="0.5212991167201597" iyz="0" izz="0.2894147916616918"/>
    </inertial>
    <visual>
      <origin rpy="0 0 0" xyz="0 0 0"/>
      <geometry>
        <mesh filename="package://kymco_maxxer90_description/meshes/wheel.stl" scale="1.0 1.0 1.0"/>
      </geometry>
      <material name="black"/>
    </visual>
    <collision>
      <origin rpy="0 0 0" xyz="0 0 0"/>
      <geometry>
        <mesh filename="package://kymco_maxxer90_description/meshes/wheel.stl" scale="1.0 1.0 1.0"/>
      </geometry>
    </collision>
  </link>
  <link name="front_left_wheel_steering_link">
    <inertial>
      <mass value="1"/>
      <origin xyz="0 0 0"/>
      <inertia ixx="0.01" ixy="0" ixz="0" iyy="0.01" iyz="0" izz="0.01"/>
    </inertial>
  </link>
  <joint name="front_left_steering_wheel_joint" type="revolute">
    <origin rpy="0 0 -1.57079632679" xyz="-0.275 0.33 0.175"/>
    <parent link="base_link"/>
    <child link="front_left_wheel_steering_link"/>
    <axis xyz="0 0 1"/>
    <mimic joint="steering_wheel_joint" multiplier="1" offset="0"/>
    <!-- TODO effort and velocity -->
    <limit effort="100.5" lower="-0.436332312999" upper="0.436332312999" velocity="4.5"/>
    <dynamics damping="3" friction="0.0"/>
  </joint>
  <joint name="front_left_wheel" type="continuous">
    <origin rpy="0 0 0" xyz="0 0 0"/>
    <parent link="front_left_wheel_steering_link"/>
    <child link="front_left_wheel_link"/>
    <axis rpy="0 0 0" xyz="0 1 0"/>
  </joint>
  <gazebo reference="front_left_wheel_link">
    <material>Gazebo/Black</material>
  </gazebo>
  &quot;

        
  <gazebo>
    <plugin filename="libroboticsgroup_gazebo_mimic_joint_plugin.so" name="front_left_mimic_joint_plugin">
      <joint>steering_wheel_joint</joint>
      <mimicJoint>front_left_steering_wheel_joint</mimicJoint>
      <hasPID/>
      <multiplier>1.0</multiplier>
      <offset>0</offset>
      <sensitiveness>0.1</sensitiveness>
      <maxEffort>100000.0</maxEffort>
    </plugin>
  </gazebo>
  <!-- <transmission name="${wheel_prefix}_wheel_steering_joint_trans"> -->
  <!-- <type>transmission_interface/SimpleTransmission</type> -->
  <!-- <joint name="${wheel_prefix}_steering_wheel_joint"> -->
  <!-- <hardwareInterface>hardware_interface/PositionJointInterface</hardwareInterface> -->
  <!-- </joint> -->
  <!-- <actuator name="${wheel_prefix}_steering_wheel_actuator"> -->
  <!-- <mechanicalReduction>1</mechanicalReduction> -->
  <!-- </actuator> -->
  <!-- </transmission> -->
  <!-- <transmission name="${wheel_prefix}_wheel_trans" type="SimpleTransmission"> -->
  <!-- <type>transmission_interface/SimpleTransmission</type> -->
  <!-- <actuator name="${wheel_prefix}_wheel_motor"> -->
  <!-- <mechanicalReduction>0</mechanicalReduction> -->
  <!-- </actuator> -->
  <!-- <joint name="${wheel_prefix}_wheel"> -->
  <!-- <hardwareInterface>hardware_interface/VelocityJointInterface</hardwareInterface> -->
  <!-- </joint> -->
  <!-- </transmission> -->
  <link name="rear_left_wheel_link">
    <inertial>
      <mass value="15.0"/>
      <origin xyz="0 0 0"/>
      <inertia ixx="0.28813432952881635" ixy="0" ixz="0" iyy="0.5212991167201597" iyz="0" izz="0.2894147916616918"/>
    </inertial>
    <visual>
      <origin rpy="0 0 0" xyz="0 0 0"/>
      <geometry>
        <mesh filename="package://kymco_maxxer90_description/meshes/wheel.stl" scale="1.0 1.0 1.0"/>
      </geometry>
      <material name="black"/>
    </visual>
    <collision>
      <origin rpy="0 0 0" xyz="0 0 0"/>
      <geometry>
        <mesh filename="package://kymco_maxxer90_description/meshes/wheel.stl" scale="1.0 1.0 1.0"/>
      </geometry>
    </collision>
  </link>
  <joint name="rear_left_wheel" type="continuous">
    <parent link="RWD"/>
    <child link="rear_left_wheel_link"/>
    <origin rpy="0 0 -1.57079632679" xyz="-0.275 0 0"/>
    <axis rpy="0 0 0" xyz="0 1 0"/>
  </joint>
  <gazebo reference="rear_left_wheel_link">
    <material>Gazebo/Black</material>
  </gazebo>
  &quot;

        
  <transmission name="rear_left_wheel_trans" type="SimpleTransmission">
    <type>transmission_interface/SimpleTransmission</type>
    <actuator name="rear_left_wheel_motor">
      <mechanicalReduction>1</mechanicalReduction>
    </actuator>
    <joint name="rear_left_wheel">
      <hardwareInterface>hardware_interface/VelocityJointInterface</hardwareInterface>
    </joint>
  </transmission>
  <link name="rear_right_wheel_link">
    <inertial>
      <mass value="15.0"/>
      <origin xyz="0 0 0"/>
      <inertia ixx="0.28813432952881635" ixy="0" ixz="0" iyy="0.5212991167201597" iyz="0" izz="0.2894147916616918"/>
    </inertial>
    <visual>
      <origin rpy="0 0 0" xyz="0 0 0"/>
      <geometry>
        <mesh filename="package://kymco_maxxer90_description/meshes/wheel.stl" scale="1.0 1.0 1.0"/>
      </geometry>
      <material name="black"/>
    </visual>
    <collision>
      <origin rpy="0 0 0" xyz="0 0 0"/>
      <geometry>
        <mesh filename="package://kymco_maxxer90_description/meshes/wheel.stl" scale="1.0 1.0 1.0"/>
      </geometry>
    </collision>
  </link>
  <joint name="rear_right_wheel" type="continuous">
    <parent link="RWD"/>
    <child link="rear_right_wheel_link"/>
    <origin rpy="0 0 1.57079632679" xyz="0.275 0 0"/>
    <axis rpy="0 0 0" xyz="0 1 0"/>
  </joint>
  <gazebo reference="rear_right_wheel_link">
    <material>Gazebo/Black</material>
  </gazebo>
  &quot;

        
  <transmission name="rear_right_wheel_trans" type="SimpleTransmission">
    <type>transmission_interface/SimpleTransmission</type>
    <actuator name="rear_right_wheel_motor">
      <mechanicalReduction>1</mechanicalReduction>
    </actuator>
    <joint name="rear_right_wheel">
      <hardwareInterface>hardware_interface/VelocityJointInterface</hardwareInterface>
    </joint>
  </transmission>
  <link name="rear_axle_link">
    <visual>
      <origin rpy="0 0 0" xyz="0 0 0"/>
      <geometry>
        <mesh filename="package://kymco_maxxer90_description/meshes/differential.stl" scale="1.0 1.0 1.0"/>
      </geometry>
      <material name="silver"/>
    </visual>
    <collision>
      <origin rpy="0 0 0" xyz="0 0 0"/>
      <geometry>
        <mesh filename="package://kymco_maxxer90_description/meshes/differential.stl" scale="1.0 1.0 1.0"/>
      </geometry>
    </collision>
  </link>
  <joint name="rear_axle_joint" type="fixed">
    <origin rpy="0 0 -1.57079632679" xyz="0.03 -0.64 0.175"/>
    <parent link="base_link"/>
    <child link="rear_axle_link"/>
  </joint>
  <gazebo reference="rear_axle_link">
    <material>Gazebo/Grey</material>
  </gazebo>
  <link name="RWD">
    <inertial>
      <mass value="5"/>
      <origin xyz="0 0 0"/>
      <inertia ixx="0.01" ixy="0" ixz="0" iyy="0.01" iyz="0" izz="0.01"/>
    </inertial>
  </link>
  <joint name="RWD_joint" type="continuous">
    <origin rpy="0 0 0" xyz="0 -0.64 0.175"/>
    <parent link="base_link"/>
    <child link="RWD"/>
    <axis xyz="-1 0 0"/>
  </joint>
  <transmission name="non_differential_trans" type="SimpleTransmission">
    <type>transmission_interface/SimpleTransmission</type>
    <actuator name="non_differential_motor">
      <mechanicalReduction>1</mechanicalReduction>
    </actuator>
    <joint name="RWD_joint">
      <hardwareInterface>hardware_interface/VelocityJointInterface</hardwareInterface>
    </joint>
  </transmission>
  <link name="front_plate_link">
    <visual>
      <origin rpy="0 0 0" xyz="0 0 0"/>
      <geometry>
        <box size="0.4 0.3 0.01"/>
      </geometry>
      <material name="silver"/>
    </visual>
    <collision>
      <origin rpy="0 0 0" xyz="0 0 0"/>
      <geometry>
        <box size="0.4 0.3 0.01"/>
      </geometry>
    </collision>
  </link>
  <joint name="front_plate_joint" type="fixed">
    <origin rpy="0 0 0" xyz="0 0.45 0.561"/>
    <parent link="base_link"/>
    <child link="front_plate_link"/>
  </joint>
  <gazebo reference="front_plate_link">
    <material>Gazebo/Grey</material>
  </gazebo>
  &quot;

    
  <link name="rear_plate_link">
    <visual>
      <origin rpy="0 0 0" xyz="0 0 0"/>
      <geometry>
        <box size="0.4 0.3 0.01"/>
      </geometry>
      <material name="silver"/>
    </visual>
    <collision>
      <origin rpy="0 0 0" xyz="0 0 0"/>
      <geometry>
        <box size="0.4 0.3 0.01"/>
      </geometry>
    </collision>
  </link>
  <joint name="rear_plate_joint" type="fixed">
    <origin rpy="-0.241660973353 0 0" xyz="0 -0.66 0.59"/>
    <parent link="base_link"/>
    <child link="rear_plate_link"/>
  </joint>
  <gazebo reference="rear_plate_link">
    <material>Gazebo/Grey</material>
  </gazebo>
  &quot;

    
  <link name="rear_trans_chassis_link">
    <visual>
      <origin rpy="0 0 0" xyz="0 0 0"/>
      <geometry>
        <box size="0.12 0.01 0.01"/>
      </geometry>
      <material name="black"/>
    </visual>
    <collision>
      <origin rpy="0 0 0" xyz="0 0 0"/>
      <geometry>
        <box size="0.12 0.01 0.01"/>
      </geometry>
    </collision>
  </link>
  <joint name="rear_trans_chassis_joint" type="fixed">
    <origin rpy="0 0 0" xyz="0 -0.46 0.39"/>
    <parent link="base_link"/>
    <child link="rear_trans_chassis_link"/>
  </joint>
  <gazebo reference="rear_trans_chassis_link">
    <material>Gazebo/Black</material>
  </gazebo>
  &quot;

    
  <link name="rear_trans_link">
    <visual>
      <origin rpy="0 0 0" xyz="0 0 0"/>
      <geometry>
        <cylinder length="0.28" radius="0.02"/>
      </geometry>
      <material name="black"/>
    </visual>
    <collision>
      <origin rpy="0 0 0" xyz="0 0 0"/>
      <geometry>
        <cylinder length="0.28" radius="0.02"/>
      </geometry>
    </collision>
  </link>
  <joint name="rear_trans_joint" type="fixed">
    <origin rpy="-0.785398163397 0 0" xyz="0 -0.56 0.29"/>
    <parent link="base_link"/>
    <child link="rear_trans_link"/>
  </joint>
  <gazebo reference="rear_trans_link">
    <material>Gazebo/Black</material>
  </gazebo>
  &quot;

    
  <link name="rear_trans_spring_link">
    <visual>
      <origin rpy="0 0 0" xyz="0 0 0"/>
      <geometry>
        <mesh filename="package://kymco_maxxer90_description/meshes/spring.stl" scale="1.0 1.0 1.0"/>
      </geometry>
      <material name="red">
        <color rgba="0.8 0 0 1"/>
      </material>
    </visual>
    <collision>
      <origin rpy="0 0 0" xyz="0 0 0"/>
      <geometry>
        <mesh filename="package://kymco_maxxer90_description/meshes/spring.stl" scale="1.0 1.0 1.0"/>
      </geometry>
    </collision>
  </link>
  <gazebo reference="rear_trans_spring_link">
    <material>Gazebo/Red</material>
  </gazebo>
  &quot;

    
  <joint name="rear_trans_spring_joint" type="fixed">
    <origin rpy="-0.785398163397 0 0" xyz="0 -0.56 0.29"/>
    <parent link="base_link"/>
    <child link="rear_trans_spring_link"/>
  </joint>
  <link name="front_right_trans_chassis_link">
    <visual>
      <origin rpy="0 0 0" xyz="0 0 0"/>
      <geometry>
        <box size="0.01 0.2 0.01"/>
      </geometry>
      <material name="black"/>
    </visual>
    <collision>
      <origin rpy="0 0 0" xyz="0 0 0"/>
      <geometry>
        <box size="0.01 0.2 0.01"/>
      </geometry>
    </collision>
  </link>
  <joint name="front_right_trans_chassis_joint" type="fixed">
    <origin rpy="0 0 0" xyz="0.075 0.33 0.4"/>
    <parent link="base_link"/>
    <child link="front_right_trans_chassis_link"/>
  </joint>
  <gazebo reference="front_right_trans_chassis_link">
    <material>Gazebo/Black</material>
  </gazebo>
  &quot;

    
  <link name="front_right_trans_link">
    <visual>
      <origin rpy="0 0 0" xyz="0 0 0"/>
      <geometry>
        <cylinder length="0.28" radius="0.02"/>
      </geometry>
      <material name="black"/>
    </visual>
    <collision>
      <origin rpy="0 0 0" xyz="0 0 0"/>
      <geometry>
        <cylinder length="0.28" radius="0.02"/>
      </geometry>
    </collision>
  </link>
  <joint name="front_right_trans_joint" type="fixed">
    <origin rpy="0.314159265359 -0.628318530718 0" xyz="0.15 0.33 0.29"/>
    <parent link="base_link"/>
    <child link="front_right_trans_link"/>
  </joint>
  <gazebo reference="front_right_trans_link">
    <material>Gazebo/Black</material>
  </gazebo>
  &quot;

    
  <link name="front_right_trans_spring_link">
    <visual>
      <origin rpy="0 0 0" xyz="0 0 0"/>
      <geometry>
        <mesh filename="package://kymco_maxxer90_description/meshes/spring.stl" scale="1.0 1.0 1.0"/>
      </geometry>
      <material name="red">
        <color rgba="0.8 0 0 1"/>
      </material>
    </visual>
    <collision>
      <origin rpy="0 0 0" xyz="0 0 0"/>
      <geometry>
        <mesh filename="package://kymco_maxxer90_description/meshes/spring.stl" scale="1.0 1.0 1.0"/>
      </geometry>
    </collision>
  </link>
  <joint name="front_right_trans_spring_joint" type="fixed">
    <origin rpy="0.314159265359 -0.628318530718 0" xyz="0.15 0.33 0.29"/>
    <parent link="base_link"/>
    <child link="front_right_trans_spring_link"/>
  </joint>
  <gazebo reference="front_right_trans_spring_link">
    <material>Gazebo/Red</material>
  </gazebo>
  &quot;

    
  <link name="front_left_trans_chassis_link">
    <visual>
      <origin rpy="0 0 0" xyz="0 0 0"/>
      <geometry>
        <box size="0.01 0.2 0.01"/>
      </geometry>
      <material name="black"/>
    </visual>
    <collision>
      <origin rpy="0 0 0" xyz="0 0 0"/>
      <geometry>
        <box size="0.01 0.2 0.01"/>
      </geometry>
    </collision>
  </link>
  <joint name="front_left_trans_chassis_joint" type="fixed">
    <origin rpy="0 0 0" xyz="-0.075 0.33 0.4"/>
    <parent link="base_link"/>
    <child link="front_left_trans_chassis_link"/>
  </joint>
  <gazebo reference="front_left_trans_chassis_link">
    <material>Gazebo/Black</material>
  </gazebo>
  &quot;

    
  <link name="front_left_trans_link">
    <visual>
      <origin rpy="0 0 0" xyz="0 0 0"/>
      <geometry>
        <cylinder length="0.28" radius="0.02"/>
      </geometry>
      <material name="black"/>
    </visual>
    <collision>
      <origin rpy="0 0 0" xyz="0 0 0"/>
      <geometry>
        <cylinder length="0.28" radius="0.02"/>
      </geometry>
    </collision>
  </link>
  <joint name="front_left_trans_joint" type="fixed">
    <origin rpy="0.314159265359 0.628318530718 0" xyz="-0.15 0.33 0.29"/>
    <parent link="base_link"/>
    <child link="front_left_trans_link"/>
  </joint>
  <gazebo reference="front_left_trans_link">
    <material>Gazebo/Black</material>
  </gazebo>
  &quot;

    
  <link name="front_left_trans_spring_link">
    <visual>
      <origin rpy="0 0 0" xyz="0 0 0"/>
      <geometry>
        <mesh filename="package://kymco_maxxer90_description/meshes/spring.stl" scale="1.0 1.0 1.0"/>
      </geometry>
      <material name="red">
        <color rgba="0.8 0 0 1"/>
      </material>
    </visual>
    <collision>
      <origin rpy="0 0 0" xyz="0 0 0"/>
      <geometry>
        <mesh filename="package://kymco_maxxer90_description/meshes/spring.stl" scale="1.0 1.0 1.0"/>
      </geometry>
    </collision>
  </link>
  <joint name="front_left_trans_spring_joint" type="fixed">
    <origin rpy="0.314159265359 0.628318530718 0" xyz="-0.15 0.33 0.29"/>
    <parent link="base_link"/>
    <child link="front_left_trans_spring_link"/>
  </joint>
  <gazebo reference="front_left_trans_spring_link">
    <material>Gazebo/Red</material>
  </gazebo>
  &quot;

    
  <gazebo>
    <plugin filename="libgazebo_ros_control.so" name="ros_control">
      <robotNamespace/>
      <robotParam>robot_description</robotParam>
      <controlPeriod>0.001</controlPeriod>
      <robotSimType>gazebo_ros_control/DefaultRobotHWSim</robotSimType>
    </plugin>
  </gazebo>
</robot>

